Workbook

Sheet Copyright
A1: MW Petroleum Corp. - A
A2: Harvard Business School Case #295-029
A3: Case Software #XLS083
A5: Copyright © 2010 President and Fellows of Harvard College. No part of this product may be reproduced, stored in a retrieval system or transmitted in any form or by any means—electronic, mechanical, photocopying, recording or otherwise—without the permission of Harvard Business School.

Sheet Table A
A1: Table A: MW Petroleum's Estimated Reserves
B3: Oil (MMB) | C3: Gas (MMCF) | D3: Total (MMBOE)
A5: Proved developed producing | B5: 73.6 | C5: 381.1 | D5: 137.1
A6: Proved developed non-producing | B6: 7.9 | C6: 61.5 | D6: 18.1
A7: Proved undeveloped | B7: 15.8 | C7: 58.5 | D7: 25.6
A8: Total Proved | B8: 97.3 | C8: 501.1 | D8: 180.8
A9: Total Probable | B9: 14.1 | C9: 70.4 | D9: 25.8
A10: Total Possible | B10: 44.5 | C10: 75.4 | D10: 57.1
A11: Total Reserves | B11: 155.9 | C11: 646.9 | D11: 263.7

Sheet Exhibit 1
A1: Exhibit 1 Amoco Corporation, Selected Historical Financial Data (in $ millions except as noted)
B3: 1986 | C3: 1987 | D3: 1988 | E3: 1989 | F3: 1990
A4: Income Statements
A5: Operating revenues | B5: 18281 | C5: 20174 | D5: 21150 | E5: 23966 | F5: 28010
A6: Consumer excise taxes and other | B6: 2064 | C6: 2282 | D6: 2769 | E6: 2794 | F6: 3571
A7: Total revenues | B7: 20345 | C7: 22456 | D7: 23919 | E7: 26760 | F7: 31581
A8: Purchased crude oil, petroleum products & merchandise | B8: 7593 | C8: 8970 | D8: 8471 | E8: 10619 | F8: 13697
A9: Operating expenses | B9: 3451 | C9: 3370 | D9: 3915 | E9: 4380 | F9: 5395
A10: Petroleum exploration expenses | B10: 925 | C10: 647 | D10: 767 | E10: 726 | F10: 693
A11: Selling and administrative expenses | B11: 1358 | C11: 1424 | D11: 1466 | E11: 1888 | F11: 1991
A12: Taxes other than income taxes | B12: 2592 | C12: 2840 | D12: 3207 | E12: 3224 | F12: 3395
A13: Depreciation, depletion and amortization | B13: 2418 | C13: 2295 | D13: 2318 | E13: 2500 | F13: 2413
A14: Interest expense | B14: 468 | C14: 410 | D14: 468 | E14: 728 | F14: 587
A15: Total costs and expenses | B15: 18805 | C15: 19956 | D15: 20612 | E15: 24065 | F15: 28171
A16: Income before income taxes | B16: 1540 | C16: 2500 | D16: 3307 | E16: 2695 | F16: 3410
... A19: Net income | B19: 747 | C19: 1360 | D19: 2063 | E19: 1610 | F19: 1913
A21: Balance Sheets
A22: Current assets | B22: 4200 | C22: 5899 | D22: 5393 | E22: 6428 | F22: 8216
A23: Investments and other | B23: 1337 | C23: 1072 | D23: 1431 | E23: 1355 | F23: 1287
A24: Properties, net | B24: 18169 | C24: 18151 | D24: 23095 | E24: 22647 | F24: 22706
A25: Total assets | B25: 23706 | C25: 25122 | D25: 29919 | E25: 30430 | F25: 32209
A27: Current liabilities | B27: 4180 | C27: 4503 | D27: 4799 | E27: 5148 | F27: 6092
A28: Short term debt | B28: 174 | C28: 468 | D28: 444 | E28: 483 | F28: 492
A29: Long term debt | B29: 3556 | C29: 3303 | D29: 6274 | E29: 5915 | F29: 5464
A30: Other liabilities | B30: 4472 | C30: 4741 | D30: 5060 | E30: 5200 | F30: 6093
A32: Shareholders’ equity | B32: 11324 | C32: 12107 | D32: 13342 | E32: 13684 | F32: 14068
A34: Financial Ratios
A35: Return on operating revenues | B35: 0.041 | C35: 0.067 | D35: 0.098 | E35: 0.067 | F35: 0.068
A36: Return on assets | B36: 0.032 | C36: 0.054 | D36: 0.069 | E36: 0.053 | F36: 0.059
A37: Return on average equity | B37: 0.065 | C37: 0.116 | D37: 0.162 | E37: 0.119 | F37: 0.138
A38: Current ratio | B38: 0.9 | C38: 1.1 | D38: 1 | E38: 1.1 | F38: 1.2
A39: Debt / capital ratio | B39: 0.191 | C39: 0.221 | D39: 0.324 | E39: 0.308 | F39: 0.288
A40: Interest coverage ratio | B40: 7.4 | C40: 8.3 | D40: 8.8 | E40: 5.3 | F40: 7.4
A41: Debt rating | B41: Aaa | C41: Aaa | D41: Aaa | E41: Aaa | F41: Aaa
A42: Price - earnings ratio | B42: 22.59 | C42: 14.7 | D42: 10 | E42: 14.4 | F42: 15.4
A43: Cash flow per share | B43: 6.3 | C43: 7.1 | D43: 8.1 | E43: 8 | F43: 8.3
A44: Common shares outstanding, (millions) | B44: 502 | C44: 515.3 | D44: 517.1 | E44: 511.5 | F44: 502
A45: Year-end stock price | B45: $32 3/4 | C45: $34 1/2 | D45: $37 1/2 | E45: $54 5/8 | F45: $52 3/8

Sheet Exhibit 2
A1: Exhibit 2 Apache Corporation, Selected Historical Financial Data (in $ millions, except as noted)
B3: 1986 | C3: 1987 | D3: 1988 | E3: 1989 | F3: 1990
A4: Income Statements
A5: Revenues | B5: 106 | C5: 100.5 | D5: 141.7 | E5: 246.9 | F5: 273.4
A7: Operating Expenses:
A8: Depreciation, depletion and amortization | B8: 82.1 | C8: 184.6 | D8: 61.4 | E8: 96.3 | F8: 116.8
A9: Operating costs | B9: 23.5 | C9: 25.5 | D9: 27.6 | E9: 42.5 | F9: 44.6
A10: Gathering and marketing costs | D10: 14.4 | E10: 31.3 | F10: 22.1
A11: Administrative, selling and other | B11: 14.6 | C11: 18.9 | D11: 16.7 | E11: 23.4 | F11: 21.5
A12: Financing costs, net | B12: 15.9 | C12: 15.1 | D12: 14.5 | E12: 21.4 | F12: 11
A14: Income from continuing operations before income taxes | B14: -30.1 | C14: -143.6 | D14: 7.1 | E14: 32 | F14: 57.4
A15: Provision for income taxes | B15: -14.8 | C15: -62.1 | D15: 1.6 | E15: 9.8 | F15: 17.2
A17: Income from continuing operations | B17: -15.3 | C17: -81.5 | D17: 5.5 | E17: 22.2 | F17: 40.2
A18: Discontinued operations:
A19: Income from discontinued operations, net of income taxes | B19: 4.4 | C19: 0.6 | D19: 2.6 | E19: 0 | F19: 0
A20: Gain on sale of discontinued operations, net of income taxes | B20: 0 | C20: 8.8 | D20: 0 | E20: 0 | F20: 0
A22: Net income before extraordinary item | B22: -10.9 | C22: -72.1 | D22: 8.1 | E22: 22.2 | F22: 40.2
A23: Extraordinary item:
A24: Gain on early extinguishment from debt, net of income taxes | B24: 0 | C24: 1.1 | D24: 1 | E24: 0 | F24: 0
A26: Net income (loss) | B26: -10.9 | C26: -71 | D26: 9.1 | E26: 22.2 | F26: 40.2
A28: Balance Sheets
A29: Current assets | B29: 89.6 | C29: 121 | D29: 109.2 | E29: 132.6 | F29: 138.5
A30: Property and equipment, net | B30: 490.7 | C30: 363.4 | D30: 570.9 | E30: 603.6 | F30: 663.4
A31: Other assets | B31: 64.3 | C31: 20 | D31: 21.6 | E31: 28.2 | F31: 27.8
A32: Total assets | B32: 644.6 | C32: 504.4 | D32: 701.7 | E32: 764.4 | F32: 829.7
A34: Current liabilities | B34: 75.6 | C34: 91.3 | D34: 87.3 | E34: 105.5 | F34: 117.6
A35: Long term debt | B35: 260.9 | C35: 238.8 | D35: 320 | E35: 198.1 | F35: 200
A37: Shareholders’ equity | B37: 207.4 | C37: 128.8 | D37: 206.9 | E37: 350.3 | F37: 386.8
A39: Financial Ratios
A40: Return on assets | D40: 0.013 | E40: 0.029 | F40: 0.048
A41: Return on average equity | D41: 0.054 | E41: 0.08 | F41: 0.109
A42: Current ratio | B42: 1.17 | C42: 1.26 | D42: 1.11 | E42: 1.23 | F42: 1.13
A43: Debt / capital ratio | B43: 0.557 | C43: 0.65 | D43: 0.607 | E43: 0.361 | F43: 0.341
A44: Interest expense (net) | B44: 15.9 | C44: 15.1 | D44: 14.5 | E44: 21.4 | F44: 11
A45: Interest coverage | D45: 1.7 | E45: 2.5 | F45: 6.2
A46: Debt rating (subordinated convertible debentures) | B46: Ba3 | C46: B2 | D46: B2 | E46: NRa | F46: Ba3
A47: Price - earnings ratio | D47: 33.2 | E47: 19.4 | F47: 17.9
A48: Cash flow per share | B48: 2.87 | C48: 2.45 | D48: 2.03 | E48: 2.7 | F48: 3.52
A49: Common shares outstanding (millions) | B49: 20.3 | C49: 20.1 | D49: 33 | E49: 44 | F49: 44.7
A50: Year-end stock price | B50: 9 | C50: $7 1//2 | D50: $7 7/8 | E50: $18 3/8 | F50: $14 5/8
...

Sheet Exhibit 3
A1: Exhibit 3 Proved Developed Reserves: Production and Cash Flow Projections ($ millions except as noted)
B3: Proved Developed Reserves | C3: 1991 | D3: 1992 | E3: 1993 | F3: 1994 | G3: 1995 | H3: 1996 | I3: 1997 | J3: 1998 | K3: 1999 | L3: 2000 | M3: 2001 | N3: 2002 | O3: 2003 | P3: 2004 | Q3: 2005
B5: Production:
A6: -1 | B6: Crude and condensates (MB) | C6: 9.4 | D6: 8.1 | E6: 7.1 | F6: 6.3 | G6: 5.3 | H6: 4.5 | I6: 3.7 | J6: 2.9 | K6: 2.4 | L6: 2.2 | M6: 1.9 | N6: 1.7 | O6: 1.5 | P6: 1.4 | Q6: 1.2
A7: -2 | B7: Gas (MMCF) | C7: 45.3 | D7: 36.8 | E7: 29.5 | F7: 25 | G7: 21.7 | H7: 18.6 | I7: 16.5 | J7: 14.9 | K7: 12.8 | L7: 11.3 | M7: 10.3 | N7: 8.5 | O7: 7.6 | P7: 6.7 | Q7: 6.2
B9: Cash Flows (in millions):
A10: -3 | B10: Revenues - oil | C10: 192 | D10: 180.4 | E10: 168.2 | F10: 154.5 | G10: 139.4 | H10: 124.5 | I10: 109.1 | J10: 94.7 | K10: 82.7 | L10: 75.7 | M10: 72 | N10: 66.7 | O10: 63.4 | P10: 59.9 | Q10: 56.6
A11: -4 | B11: Revenues - gas | C11: 90.5 | D11: 82.1 | E11: 73.5 | F11: 67.8 | G11: 64.1 | H11: 59.2 | I11: 56.7 | J11: 54.2 | K11: 50.4 | L11: 47.6 | M11: 45.8 | N11: 41.1 | O11: 38.2 | P11: 36.9 | Q11: 36.1
A12: -5 | B12: Total revenues | C12: 282.5 | D12: 262.5 | E12: 241.7 | F12: 222.3 | G12: 203.5 | H12: 183.7 | I12: 165.8 | J12: 148.9 | K12: 133.1 | L12: 123.3 | M12: 117.8 | N12: 107.7 | O12: 101.6 | P12: 96.8 | Q12: 92.7
A14: -6 | B14: Direct production taxes | C14: 25.5 | D14: 23.6 | E14: 21.6 | F14: 19.9 | G14: 18 | H14: 16.2 | I14: 14.4 | J14: 12.7 | K14: 11.4 | L14: 10.5 | M14: 9.8 | N14: 9.1 | O14: 8.5 | P14: 8.1 | Q14: 7.7
A15: -7 | B15: Direct operating expense | C15: 79.9 | D15: 80.3 | E15: 79.8 | F15: 78.9 | G15: 76 | H15: 71 | I15: 63.8 | J15: 56.1 | K15: 49.9 | L15: 48.2 | M15: 45.5 | N15: 44.1 | O15: 44.5 | P15: 43.7 | Q15: 43
A16: -8 | B16: Overhead | C16: 33.9 | D16: 32.2 | E16: 28.6 | F16: 25.9 | G16: 23 | H16: 20.4 | I16: 18.3 | J16: 16.1 | K16: 13.9 | L16: 12.6 | M16: 10.8 | N16: 9.7 | O16: 9 | P16: 8.3 | Q16: 7.8
A17: -9 | B17: Fin. book DD&A | C17: 58 | D17: 45.2 | E17: 35.6 | F17: 29.1 | G17: 23.8 | H17: 19.1 | I17: 19.6 | J17: 16.6 | K17: 13.3 | L17: 10.7 | M17: 9 | N17: 7.5 | O17: 6.3 | P17: 5.3 | Q17: 4.5
A18: -10 | B18: Net income before taxes | C18: 85.2 | D18: 81.2 | E18: 76.1 | F18: 68.6 | G18: 62.7 | H18: 57 | I18: 49.7 | J18: 47.4 | K18: 44.6 | L18: 41.4 | M18: 42.8 | N18: 37.3 | O18: 33.3 | P18: 31.3 | Q18: 29.7
A19: -11 | B19: Federal and state income taxes:
A20: -12 | B20: Current | C20: 48.5 | D20: 44.4 | E20: 39.3 | F20: 34.1 | G20: 29.9 | H20: 25.9 | I20: 23.6 | J20: 21.5 | K20: 19.3 | L20: 17.5 | M20: 17.4 | N20: 15.2 | O20: 13.4 | P20: 12.7 | Q20: 12
A21: -13 | B21: Deferred | C21: -19.1 | D21: -15.2 | E21: -11.8 | F21: -9.5 | G21: -7.7 | H21: -5.9 | I21: -6.2 | J21: -5.1 | K21: -3.9 | L21: -3.1 | M21: -2.5 | N21: -2.2 | O21: -1.8 | P21: -1.4 | Q21: -1.2
A22: -14 | B22: Total income taxes | C22: 29.4 | D22: 29.2 | E22: 27.4 | F22: 24.6 | G22: 22.3 | H22: 20 | I22: 17.4 | J22: 16.4 | K22: 15.4 | L22: 14.4 | M22: 14.9 | N22: 13 | O22: 11.7 | P22: 11.3 | Q22: 10.8
A23: -15 | B23: Profit contribution | C23: 55.8 | D23: 52 | E23: 48.6 | F23: 43.9 | G23: 40.4 | H23: 37 | I23: 32.2 | J23: 31 | K23: 29.2 | L23: 27 | M23: 27.9 | N23: 24.3 | O23: 21.7 | P23: 20 | Q23: 18.9
A24: -16 | B24: Non-cash charges | C24: 38.9 | D24: 30.1 | E24: 23.7 | F24: 19.6 | G24: 16.1 | H24: 13.2 | I24: 13.5 | J24: 11.5 | K24: 9.5 | L24: 7.7 | M24: 6.4 | N24: 5.3 | O24: 4.5 | P24: 4 | Q24: 3.3
A25: -17 | B25: Cash from operations | C25: 94.7 | D25: 82 | E25: 72.3 | F25: 63.5 | G25: 56.6 | H25: 50.3 | I25: 45.7 | J25: 42.5 | K25: 38.7 | L25: 34.6 | M25: 34.4 | N25: 29.6 | O25: 26.2 | P25: 24 | Q25: 22.2
A26: -18 | B26: Capital expenditures | C26: 5.4 | D26: 2 | E26: 2.7 | F26: 0.5 | G26: 0.6 | H26: 0.8 | I26: 0.8 | J26: 0.6 | K26: 1.1 | L26: 0.4 | M26: 0.1 | N26: 0.1 | O26: 0.1 | P26: 0.5 | Q26: 0.1
A28: -19 | B28: Cash flow | C28: 89.4 | D28: 80 | E28: 69.6 | F28: 63 | G28: 56 | H28: 49.5 | I28: 44.9 | J28: 41.9 | K28: 37.6 | L28: 34.3 | M28: 34.2 | N28: 29.5 | O28: 26.1 | P28: 23.5 | Q28: 22.1
A30: -20 | B30: Terminal value | Q30: 92.1
A32: -21 | B32: Cumulative cash flow | C32: 89.4 | D32: =SUM($C$28:D28) -> 169.4 | E32: =SUM($C$28:E28) -> 239 | F32: =SUM($C$28:F28) -> 302 | G32: =SUM($C$28:G28) -> 358 | H32: =SUM($C$28:H28) -> 407.5 | I32: =SUM($C$28:I28) -> 452.4 | J32: =SUM($C$28:J28) -> 494.3 | K32: =SUM($C$28:K28) -> 531.9 | ... P32: =SUM($C$28:P28) -> 679.5 | Q32: =SUM($C$28:Q28)+Q30 -> 793.7
A35: Notes to follow Exhibit 7.
B38: Tax Rate | C38: =C22/C18 -> 0.34507042 | D38: =D22/D18 -> 0.35960591 | E38: =E22/E18 -> 0.36005256 | F38: =F22/F18 -> 0.35860058 | G38: =G22/G18 -> 0.35566188 | H38: =H22/H18 -> 0.35087719 | I38: =I22/I18 -> 0.3501006 | J38: =J22/J18 -> 0.34599156 | ... Q38: =Q22/Q18 -> 0.36363636 | S38: =AVERAGE(C38:Q38) -> 0.35278298

Sheet Exhibit 4
A1: Exhibit 4 Proved Undeveloped Reserves: Production and Cash Flow Projections ($ millions except as noted)
B3: Proved Undeveloped Reserves | C3: Year 1 | D3: 2 | E3: 3 | F3: 4 | G3: 5 | H3: 6 | I3: 7 | J3: 8 | K3: 9 | L3: 10 | M3: 11 | N3: 12 | O3: 13 | P3: 14 | Q3: 15
B5: Production:
A6: -1 | B6: Crude and condensates (MB) | C6: 0.3 | D6: 0.6 | E6: 0.5 | F6: 0.5 | G6: 0.5 | H6: 0.5 | I6: 0.5 | J6: 0.7 | K6: 0.8 | L6: 0.7 | M6: 0.7 | N6: 0.7 | O6: 0.7 | P6: 0.7 | Q6: 0.6
A7: -2 | B7: Gas (MMCF) | C7: 1.7 | D7: 4.9 | E7: 5.6 | F7: 3.3 | G7: 2.3 | H7: 2 | I7: 2 | J7: 2.2 | K7: 2.3 | L7: 1.9 | M7: 1.6 | N7: 1.3 | O7: 1.3 | P7: 1 | Q7: 0.9
B9: Cash Flows (in millions):
A10: -3 | B10: Revenues - oil | C10: 6 | D10: 14 | E10: 12.9 | F10: 11.8 | G10: 12.3 | H10: 13.2 | I10: 16.1 | J10: 21 | K10: 27.1 | L10: 25.2 | M10: 25.3 | N10: 26.8 | O10: 28.7 | P10: 30.9 | Q10: 29.3
A11: -4 | B11: Revenues - gas | C11: 3.4 | D11: 11.3 | E11: 14.5 | F11: 9.1 | G11: 6.7 | H11: 6.2 | I11: 6.6 | J11: 7.1 | K11: 8.2 | L11: 7.2 | M11: 6.6 | N11: 5.5 | O11: 5.2 | P11: 5.2 | Q11: 4.5
A12: -5 | B12: Total revenues | C12: 9.4 | D12: 25.3 | E12: 27.4 | F12: 20.9 | G12: 19 | H12: 19.4 | I12: 22.7 | J12: 28.1 | K12: 35.3 | L12: 32.4 | M12: 31.9 | N12: 32.3 | O12: 33.9 | P12: 36.1 | Q12: 33.8
A14: -6 | B14: Direct production taxes | C14: 0.9 | D14: 2.4 | E14: 2.3 | F14: 1.8 | G14: 1.7 | H14: 1.7 | I14: 2 | J14: 2.5 | K14: 3.1 | L14: 2.8 | M14: 2.8 | N14: 3 | O14: 3.1 | P14: 2.9 | Q14: 3
A15: -7 | B15: Direct operating expense | C15: 1.2 | D15: 1.5 | E15: 2 | F15: 2.3 | G15: 2.8 | H15: 3.4 | I15: 3.3 | J15: 3.3 | K15: 4.5 | L15: 3.4 | M15: 3.7 | N15: 4.2 | O15: 4.5 | P15: 4.7 | Q15: 4.8
A16: -8 | B16: Overhead | C16: 1.1 | D16: 3.1 | E16: 3.2 | F16: 2.4 | G16: 2.1 | H16: 2.2 | I16: 2.5 | J16: 3 | K16: 3.7 | L16: 3.3 | M16: 2.9 | N16: 2.9 | O16: 3 | P16: 3.1 | Q16: 2.8
A17: -9 | B17: Fin. book DD&A | C17: 12.3 | D17: 12.6 | E17: 10.6 | F17: 9.3 | G17: 8.1 | H17: 6.7 | I17: 6.8 | J17: 5.8 | K17: 4.6 | L17: 3.7 | M17: 4.3 | N17: 3.6 | O17: 3 | P17: 2.5 | Q17: 2.1
A18: -10 | B18: Net income before taxes | C18: -6.2 | D18: 5.7 | E18: 9.2 | F18: 5.1 | G18: 4.2 | H18: 5.5 | I18: 8.1 | J18: 13.5 | K18: 19.5 | L18: 19.2 | M18: 18.2 | N18: 18.6 | O18: 20.3 | P18: 22.8 | Q18: 21.1
A19: -11 | B19: Federal and state income taxes:
A20: -12 | B20: Current | C20: 2.1 | D20: 6.4 | E20: 7 | F20: 5 | G20: 4.3 | H20: 4.1 | I20: 5.1 | J20: 6.5 | K20: 8 | L20: 7.7 | M20: 7.6 | N20: 7.5 | O20: 7.9 | P20: 8.8 | Q20: 8.1
A21: -13 | B21: Deferred | C21: -4.1 | D21: -4.2 | E21: -3.5 | F21: -3 | G21: -2.6 | H21: -2.1 | I21: -2.1 | J21: -1.8 | K21: -1.3 | L21: -1.1 | M21: -1.2 | N21: -1 | O21: -0.9 | P21: -0.7 | Q21: -0.6
A22: -14 | B22: Total income taxes | C22: -2 | D22: 2.2 | E22: 3.5 | F22: 2 | G22: 1.7 | H22: 2.1 | I22: 2.9 | J22: 4.7 | K22: 6.7 | L22: 6.6 | M22: 6.3 | N22: 6.5 | O22: 7.1 | P22: 8.1 | Q22: 7.5
A23: -15 | B23: Profit contribution | C23: -4.2 | D23: 3.5 | E23: 5.8 | F23: 3.1 | G23: 2.6 | H23: 3.4 | I23: 5.1 | J23: 8.8 | K23: 12.8 | L23: 12.6 | M23: 11.8 | N23: 12.1 | O23: 13.3 | P23: 14.7 | Q23: 13.5
A24: -16 | B24: Non-cash charges | C24: 8.3 | D24: 8.4 | E24: 7.1 | F24: 6.3 | G24: 5.5 | H24: 4.6 | I24: 4.7 | J24: 4 | K24: 3.2 | L24: 2.6 | M24: 3.1 | N24: 2.5 | O24: 2.2 | P24: 1.9 | Q24: 1.6
A25: -17 | B25: Cash from operations | C25: 4 | D25: 11.9 | E25: 12.9 | F25: 9.3 | G25: 8.1 | H25: 8 | I25: 9.8 | J25: 12.8 | K25: 16 | L25: 15.2 | M25: 14.9 | N25: 14.7 | O25: 15.4 | P25: 16.6 | Q25: 15.1
A26: -18 | B26: Capital expenditures | C26: 17.5 | D26: 17.7 | E26: 5.3 | F26: 4.1 | G26: 3.5 | H26: 1.3 | I26: 0.1 | J26: 0.3 | K26: 0 | L26: 0.1 | M26: 8.1 | N26: 0 | O26: 0.2 | P26: 0 | Q26: 0
A28: -19 | B28: Cash flow | C28: -13.5 | D28: -5.8 | E28: 7.6 | F28: 5.2 | G28: 4.6 | H28: 6.7 | I28: 9.7 | J28: 12.5 | K28: 16 | L28: 15.1 | M28: 6.8 | N28: 14.7 | O28: 15.2 | P28: 16.5 | Q28: 15.1
A30: -20 | B30: Terminal value | Q30: 67.8
A32: -21 | B32: Cumulative cash flow | C32: -13.5 | D32: -19.3 | E32: -11.7 | F32: -6.4 | G32: -1.9 | H32: 4.9 | I32: 14.6 | J32: 27.1 | K32: 43.1 | L32: 58.2 | M32: 65 | N32: 79.7 | O32: 95 | P32: 111.5 | Q32: 194.3
A35: Notes follow Exhibit 7.
B38: Tax Rate | C38: =C22/C18 -> 0.32258065 | D38: =D22/D18 -> 0.38596491 | E38: =E22/E18 -> 0.38043478 | F38: =F22/F18 -> 0.39215686 | G38: =G22/G18 -> 0.4047619 | H38: =H22/H18 -> 0.38181818 | I38: =I22/I18 -> 0.35802469 | J38: =J22/J18 -> 0.34814815 | ... Q38: =Q22/Q18 -> 0.35545024 | S38: =AVERAGE(C38:Q38) -> 0.36115421

Sheet Exhibit 5
A1: Exhibit 5 Probable Reserves: Production and Cash Flow Projections ($ millions except as noted)
B3: Probable Reserves | C3: Year 1 | D3: 2 | E3: 3 | F3: 4 | G3: 5 | H3: 6 | I3: 7 | J3: 8 | K3: 9 | L3: 10 | M3: 11 | N3: 12 | O3: 13 | P3: 14 | Q3: 15
B5: Production:
A6: -1 | B6: Crude and condensates (MB) | C6: 0.2 | D6: 0.3 | E6: 0.4 | F6: 0.4 | G6: 0.5 | H6: 0.5 | I6: 0.7 | J6: 0.9 | K6: 0.8 | L6: 0.7 | M6: 0.6 | N6: 0.5 | O6: 0.4 | P6: 0.4 | Q6: 0.3
A7: -2 | B7: Gas (MMCF) | C7: 2.8 | D7: 4.2 | E7: 4.9 | F7: 5.3 | G7: 4.2 | H7: 3.8 | I7: 4.5 | J7: 4.2 | K7: 3.3 | L7: 2.4 | M7: 2.1 | N7: 2 | O7: 1.5 | P7: 1.3 | Q7: 1.1
B9: Cash Flows (in millions):
A10: -3 | B10: Revenues - oil | C10: 3.7 | D10: 6.3 | E10: 8 | F10: 9.6 | G10: 13.3 | H10: 14.3 | I10: 17 | J10: 19.6 | K10: 20.3 | L10: 19.8 | M10: 18.6 | N10: 17.1 | O10: 15.8 | P10: 14.5 | Q10: 13.4
A11: -4 | B11: Revenues - gas | C11: 5.8 | D11: 9.4 | E11: 11.6 | F11: 14.1 | G11: 12.3 | H11: 12.3 | I11: 13 | J11: 11.6 | K11: 10.7 | L11: 9.3 | M11: 9.5 | N11: 10.1 | O11: 8.8 | P11: 8.1 | Q11: 7.3
A12: -5 | B12: Total revenues | C12: 9.5 | D12: 15.7 | E12: 19.5 | F12: 23.7 | G12: 25.7 | H12: 26.6 | I12: 30 | J12: 31.2 | K12: 31 | L12: 29.2 | M12: 28.1 | N12: 27.2 | O12: 24.7 | P12: 22.6 | Q12: 20.6
A14: -6 | B14: Direct production taxes | C14: 0.8 | D14: 1.3 | E14: 1.7 | F14: 2 | G14: 2.2 | H14: 2.3 | I14: 2.7 | J14: 2.9 | K14: 3.1 | L14: 3 | M14: 2.8 | N14: 2.7 | O14: 2.5 | P14: 2.3 | Q14: 2.1
A15: -7 | B15: Direct operating expense | C15: 0.4 | D15: 0.7 | E15: 0.8 | F15: 2.6 | G15: 4.4 | H15: 4.7 | I15: 5.3 | J15: 5.7 | K15: 6 | L15: 6.4 | M15: 7 | N15: 7.4 | O15: 7.4 | P15: 7.3 | Q15: 7.2
A16: -8 | B16: Overhead | C16: 1.3 | D16: 1.9 | E16: 2.3 | F16: 2.8 | G16: 3 | H16: 2.9 | I16: 3.1 | J16: 3.3 | K16: 3 | L16: 2.8 | M16: 2.6 | N16: 2.5 | O16: 2.2 | P16: 2 | Q16: 1.9
A17: -9 | B17: Fin. book DD&A | C17: 0.4 | D17: 0.8 | E17: 1.2 | F17: 2.5 | G17: 1.6 | H17: 1.3 | I17: 1.5 | J17: 2 | K17: 1.5 | L17: 1.4 | M17: 1.4 | N17: 1.4 | O17: 1.4 | P17: 1.3 | Q17: 1.3
A18: -10 | B18: Net income before taxes | C18: 6.6 | D18: 11 | E18: 13.5 | F18: 13.8 | G18: 14.5 | H18: 15.4 | I18: 17.3 | J18: 17.4 | K18: 17.5 | L18: 15.5 | M18: 14.3 | N18: 13.3 | O18: 11.3 | P18: 9.6 | Q18: 8.1
A19: -11 | B19: Federal and state income taxes:
A20: -12 | B20: Current | C20: 2.9 | D20: 3.7 | E20: 4.8 | F20: 4.8 | G20: 3.8 | H20: 4.2 | I20: 5.5 | J20: 5.8 | K20: 5.5 | L20: 5.4 | M20: 5 | N20: 4.7 | O20: 4 | P20: 3.5 | Q20: 3
A21: -13 | B21: Deferred | C21: -0.2 | D21: 0 | E21: -0.2 | F21: -0.2 | G21: 0.3 | H21: 0.3 | I21: 0.1 | J21: (0.0) | K21: 0 | L21: 0 | M21: 0 | N21: 0 | O21: 0 | P21: 0 | Q21: 0
A22: -14 | B22: Total income taxes | C22: 2.6 | D22: 3.7 | E22: 4.6 | F22: 4.5 | G22: 4.1 | H22: 4.5 | I22: 5.6 | J22: 5.7 | K22: 5.6 | L22: 5.4 | M22: 5 | N22: 4.7 | O22: 4 | P22: 3.5 | Q22: 3
A23: -15 | B23: Profit contribution | C23: 4 | D23: 7.3 | E23: 8.9 | F23: 9.3 | G23: 10.5 | H23: 10.8 | I23: 11.7 | J23: 11.7 | K23: 11.9 | L23: 10.1 | M23: 9.3 | N23: 8.6 | O23: 7.2 | P23: 6.1 | Q23: 5.1
A24: -16 | B24: Non-cash charges | C24: 0.2 | D24: 0.8 | E24: 1.1 | F24: 2.2 | G24: 1.9 | H24: 1.6 | I24: 1.6 | J24: 1.9 | K24: 1.6 | L24: 1.4 | M24: 1.4 | N24: 1.4 | O24: 1.4 | P24: 1.4 | Q24: 1.3
A25: -17 | B25: Cash from operations | C25: 4.2 | D25: 8.1 | E25: 9.9 | F25: 11.5 | G25: 12.3 | H25: 12.4 | I25: 13.4 | J25: 13.6 | K25: 13.5 | L25: 11.5 | M25: 10.7 | N25: 10 | O25: 8.6 | P25: 7.5 | Q25: 6.4
A26: -18 | B26: Capital expenditures | C26: 10 | D26: 4.3 | E26: 11.4 | F26: 14 | G26: 2.6 | H26: 0.5 | I26: 0.3 | J26: 0.6 | K26: 0.3 | L26: 0.5 | M26: 0.5 | N26: 0 | O26: 0.2 | P26: 0.5 | Q26: 0
A28: -19 | B28: Cash flow | C28: -5.8 | D28: 3.8 | E28: -1.5 | F28: -2.5 | G28: 9.7 | H28: 11.9 | I28: 13.1 | J28: 13 | K28: 13.2 | L28: 11 | M28: 10.2 | N28: 10 | O28: 8.4 | P28: 7 | Q28: 6.4
A30: -20 | B30: Terminal value | Q30: 51
A32: -21 | B32: Cumulative cash flow | C32: -5.8 | D32: -2 | E32: -3.5 | F32: -6 | G32: 3.7 | H32: 15.7 | I32: 28.8 | J32: 41.8 | K32: 55 | L32: 66 | M32: 76.3 | N32: 86.3 | O32: 94.7 | P32: 101.7 | Q32: 159
A35: Notes follow Exhibit 7.
B38: Tax Rate | C38: =C22/C18 -> 0.39393939 | D38: =D22/D18 -> 0.33636364 | E38: =E22/E18 -> 0.34074074 | F38: =F22/F18 -> 0.32608696 | G38: =G22/G18 -> 0.28275862 | H38: =H22/H18 -> 0.29220779 | I38: =I22/I18 -> 0.32369942 | J38: =J22/J18 -> 0.32758621 | ... Q38: =Q22/Q18 -> 0.37037037

Sheet Exhibit 6
A1: Exhibit 6 Possible Reserves: Production and Cash Flow Projections ($ millions except as noted)
B3: Possible Reserves | C3: Year 1 | D3: 2 | E3: 3 | F3: 4 | G3: 5 | H3: 6 | I3: 7 | J3: 8 | K3: 9 | L3: 10 | M3: 11 | N3: 12 | O3: 13 | P3: 14 | Q3: 15
B5: Production:
A6: -1 | B6: Crude and condensates (MB) | C6: 0.1 | D6: 0.8 | E6: 0.9 | F6: 0.8 | G6: 0.8 | H6: 1 | I6: 1.6 | J6: 2.1 | K6: 2.4 | L6: 2.3 | M6: 2 | N6: 1.7 | O6: 1.6 | P6: 1.4 | Q6: 1.2
A7: -2 | B7: Gas (MMCF) | C7: 0.5 | D7: 3.5 | E7: 3.8 | F7: 3.9 | G7: 3.6 | H7: 3.7 | I7: 3.2 | J7: 3 | K7: 3.2 | L7: 2.8 | M7: 1.9 | N7: 1.3 | O7: 1.4 | P7: 1.2 | Q7: 1
B9: Cash Flows (in millions):
A10: -3 | B10: Revenues - oil | C10: 2.1 | D10: 10.1 | E10: 13.2 | F10: 14.4 | G10: 18 | H10: 24.1 | I10: 42.3 | J10: 59.1 | K10: 67.4 | L10: 69.4 | M10: 66.8 | N10: 62.7 | O10: 59.7 | P10: 56.4 | Q10: 52
A11: -4 | B11: Revenues - gas | C11: 0.6 | D11: 3.6 | E11: 5.1 | F11: 6.9 | G11: 7.2 | H11: 7.7 | I11: 7.7 | J11: 7 | K11: 7.8 | L11: 9.3 | M11: 8.1 | N11: 6.1 | O11: 5.9 | P11: 5.9 | Q11: 5.7
A12: -5 | B12: Total revenues | C12: 2.7 | D12: 13.7 | E12: 18.3 | F12: 21.3 | G12: 25.1 | H12: 31.8 | I12: 50 | J12: 66.1 | K12: 75.2 | L12: 78.7 | M12: 74.9 | N12: 68.8 | O12: 65.7 | P12: 62.3 | Q12: 57.7
A14: -6 | B14: Direct production taxes | C14: 0.3 | D14: 1.2 | E14: 1.6 | F14: 1.8 | G14: 2.2 | H14: 2.8 | I14: 5 | J14: 6.8 | K14: 7.9 | L14: 8 | M14: 7.1 | N14: 6.7 | O14: 6.4 | P14: 6.1 | Q14: 5.6
A15: -7 | B15: Direct operating expense | C15: 0.2 | D15: 1 | E15: 1.5 | F15: 2.1 | G15: 6.5 | H15: 13.1 | I15: 21.2 | J15: 31.9 | K15: 33 | L15: 35.1 | M15: 26.4 | N15: 26.3 | O15: 25.7 | P15: 25.8 | Q15: 25.6
A16: -8 | B16: Overhead | C16: 0.4 | D16: 1.6 | E16: 2.1 | F16: 2.5 | G16: 2.9 | H16: 3.4 | I16: 5.2 | J16: 6.9 | K16: 7.3 | L16: 7.6 | M16: 6.9 | N16: 6.3 | O16: 5.9 | P16: 5.7 | Q16: 5.3
A17: -9 | B17: Fin. book DD&A | C17: 0.7 | D17: 1.4 | E17: 2.2 | F17: 4.9 | G17: 3.5 | H17: 3.1 | I17: 3.6 | J17: 4.5 | K17: 3.5 | L17: 3.3 | M17: 3.3 | N17: 3.2 | O17: 3.2 | P17: 3.1 | Q17: 3.1
A18: -10 | B18: Net income before taxes | C18: 1.2 | D18: 8.5 | E18: 10.9 | F18: 10 | G18: 10 | H18: 9.4 | I18: 15 | J18: 16 | K18: 23.4 | L18: 24.6 | M18: 31.1 | N18: 26.2 | O18: 24.5 | P18: 21.6 | Q18: 18.1
A19: -11 | B19: Federal and state income taxes:
A20: -12 | B20: Current | C20: 0.8 | D20: 3.1 | E20: 4.2 | F20: 4.4 | G20: 3.2 | H20: 3.2 | I20: 5.4 | J20: 6.1 | K20: 7.8 | L20: 8.9 | M20: 10.9 | N20: 9.4 | O20: 8.8 | P20: 7.9 | Q20: 6.7
A21: -13 | B21: Deferred | C21: -0.4 | D21: (0.0) | E21: -0.3 | F21: -0.5 | G21: 0.7 | H21: 0.7 | I21: 0.2 | J21: -0.2 | K21: 0.2 | L21: 0 | M21: 0 | N21: 0 | O21: 0 | P21: 0 | Q21: 0
A22: -14 | B22: Total income taxes | C22: 0.3 | D22: 3.1 | E22: 4 | F22: 3.9 | G22: 3.8 | H22: 3.9 | I22: 5.6 | J22: 6 | K22: 8 | L22: 8.9 | M22: 11 | N22: 9.4 | O22: 8.8 | P22: 7.9 | Q22: 6.8
A23: -15 | B23: Profit contribution | C23: 0.8 | D23: 5.4 | E23: 7 | F23: 6.2 | G23: 6.1 | H23: 5.5 | I23: 9.3 | J23: 10 | K23: 15.4 | L23: 15.7 | M23: 20.2 | N23: 16.9 | O23: 15.7 | P23: 13.7 | Q23: 11.4
A24: -16 | B24: Non-cash charges | C24: 0.3 | D24: 1.4 | E24: 1.9 | F24: 4.4 | G24: 4.2 | H24: 3.8 | I24: 3.8 | J24: 4.4 | K24: 3.7 | L24: 3.3 | M24: 3.3 | N24: 3.3 | O24: 3.2 | P24: 3.2 | Q24: 3.1
A25: -17 | B25: Cash from operations | C25: 1.1 | D25: 6.8 | E25: 8.9 | F25: 10.6 | G25: 10.4 | H25: 9.3 | I25: 13.2 | J25: 14.4 | K25: 19.1 | L25: 19.1 | M25: 23.5 | N25: 20.1 | O25: 18.9 | P25: 16.9 | Q25: 14.5
A26: -18 | B26: Capital expenditures | C26: 9.7 | D26: 9.8 | E26: 22.4 | F26: 38.9 | G26: 27.4 | H26: 6.8 | I26: 0.7 | J26: 1 | K26: 0.7 | L26: 3 | M26: 2.3 | N26: 0 | O26: 0.1 | P26: 0 | Q26: 0
A28: -19 | B28: Cash flow | C28: -8.6 | D28: -2.9 | E28: -13.5 | F28: -28.4 | G28: -17.1 | H28: 2.5 | I28: 12.5 | J28: 13.4 | K28: 18.5 | L28: 16.1 | M28: 21.2 | N28: 20.1 | O28: 18.8 | P28: 16.8 | Q28: 14.4
A30: -20 | B30: Terminal value | Q30: 72.3
A32: -21 | B32: Cumulative cash flow | C32: -8.6 | D32: -11.6 | E32: -25.1 | F32: -53.5 | G32: -70.6 | H32: -68.1 | I32: -55.6 | J32: -42.2 | K32: -23.8 | L32: -7.7 | M32: 13.5 | N32: 33.6 | O32: 52.4 | P32: 69.2 | Q32: 155.9
A35: Notes follow Exhibit 7.
B38: Tax Rate | C38: =C22/C18 -> 0.25 | D38: =D22/D18 -> 0.36470588 | E38: =E22/E18 -> 0.36697248 | F38: =F22/F18 -> 0.39 | G38: =G22/G18 -> 0.38 | H38: =H22/H18 -> 0.41489362 | I38: =I22/I18 -> 0.37333333 | J38: =J22/J18 -> 0.375 | ... Q38: =Q22/Q18 -> 0.37569061

Sheet Exhibit 7
A1: Exhibit 7 Aggregated MW Production and Cash Flow Projections ($ millions except as noted)
B3: Aggregated MW Projections | C3: Year 1 | D3: 2 | E3: 3 | F3: 4 | G3: 5 | H3: 6 | I3: 7 | J3: 8 | K3: 9 | L3: 10 | M3: 11 | N3: 12 | O3: 13 | P3: 14 | Q3: 15
B5: Production:
A6: -1 | B6: Net crude and condensates (MB) | C6: 10 | D6: 9.8 | E6: 8.9 | F6: 8.1 | G6: 7.1 | H6: 6.5 | I6: 6.5 | J6: 6.6 | K6: 6.4 | L6: 5.8 | M6: 5.2 | N6: 4.6 | O6: 4.3 | P6: 3.8 | Q6: 3.4
A7: -2 | B7: Net gas (MMCF) | C7: 50.2 | D7: 49.5 | E7: 43.7 | F7: 37.5 | G7: 31.8 | H7: 28.1 | I7: 26.2 | J7: 24.4 | K7: 21.6 | L7: 18.3 | M7: 15.9 | N7: 13.1 | O7: 11.8 | P7: 10.2 | Q7: 9.3
B9: Cash Flows (in millions):
A10: -3 | B10: Revenues - oil | C10: 203.9 | D10: 210.9 | E10: 202.3 | F10: 190.3 | G10: 183 | H10: 176.1 | I10: 184.5 | J10: 194.4 | K10: 197.5 | L10: 190.2 | M10: 182.7 | N10: 173.2 | O10: 167.7 | P10: 161.7 | Q10: 151.3
A11: -4 | B11: Revenues - gas | C11: 100.3 | D11: 106.3 | E11: 104.7 | F11: 97.9 | G11: 90.3 | H11: 85.4 | I11: 84 | J11: 80 | K11: 77.2 | L11: 73.4 | M11: 70 | N11: 62.8 | O11: 58.1 | P11: 56.1 | Q11: 53.5
A12: -5 | B12: Total revenues | C12: 304.1 | D12: 317.2 | E12: 306.9 | F12: 288.3 | G12: 273.3 | H12: 261.5 | I12: 268.5 | J12: 274.4 | K12: 274.7 | L12: 263.6 | M12: 252.7 | N12: 236 | O12: 225.8 | P12: 217.8 | Q12: 204.8
A14: -6 | B14: Direct production taxes | C14: 27.5 | D14: 28.5 | E14: 27.3 | F14: 25.5 | G14: 24.1 | H14: 23 | I14: 24.1 | J14: 25 | K14: 25.4 | L14: 24.3 | M14: 22.5 | N14: 21.5 | O14: 20.4 | P14: 19.4 | Q14: 18.4
A15: -7 | B15: Direct operating expense | C15: 81.7 | D15: 83.5 | E15: 84.1 | F15: 85.9 | G15: 89.7 | H15: 92.2 | I15: 93.7 | J15: 97 | K15: 93.3 | L15: 93.2 | M15: 82.6 | N15: 82 | O15: 82 | P15: 81.5 | Q15: 80.6
A16: -8 | B16: Overhead | C16: 36.6 | D16: 38.7 | E16: 36.3 | F16: 33.6 | G16: 31 | H16: 28.8 | I16: 29.2 | J16: 29.3 | K16: 27.9 | L16: 26.3 | M16: 23.2 | N16: 21.4 | O16: 20.1 | P16: 19.1 | Q16: 17.8
A17: -9 | B17: Fin. book DD&A | C17: 71.4 | D17: 60 | E17: 49.6 | F17: 45.7 | G17: 37 | H17: 30.2 | I17: 31.6 | J17: 28.9 | K17: 23 | L17: 19.2 | M17: 18 | N17: 15.7 | O17: 13.8 | P17: 12.3 | Q17: 11
A18: -10 | B18: Net income before taxes | C18: 86.8 | D18: 106.5 | E18: 109.7 | F18: 97.5 | G18: 91.5 | H18: 87.2 | I18: 90 | J18: 94.3 | K18: 105 | L18: 100.7 | M18: 106.5 | N18: 95.5 | O18: 89.5 | P18: 85.4 | Q18: 77
A19: -11 | B19: Federal and state income taxes:
A20: -12 | B20: Current | C20: 54.2 | D20: 57.6 | E20: 55.3 | F20: 48.3 | G20: 41.2 | H20: 37.4 | I20: 39.5 | J20: 39.9 | K20: 40.7 | L20: 39.4 | M20: 40.9 | N20: 36.8 | O20: 34.2 | P20: 32.8 | Q20: 29.8
A21: -13 | B21: Deferred | C21: -23.8 | D21: -19.4 | E21: -15.8 | F21: -13.2 | G21: -9.3 | H21: -7 | I21: -7.9 | J21: -7.1 | K21: -4.9 | L21: -4.1 | M21: -3.7 | N21: -3.2 | O21: -2.6 | P21: -2 | Q21: -1.8
A22: -14 | B22: Total income taxes | C22: 30.4 | D22: 38.2 | E22: 39.5 | F22: 35 | G22: 31.9 | H22: 30.5 | I22: 31.6 | J22: 32.8 | K22: 35.8 | L22: 35.3 | M22: 37.2 | N22: 33.6 | O22: 31.6 | P22: 30.8 | Q22: 28.1
A23: -15 | B23: Profit contribution | C23: 56.4 | D23: 68.3 | E23: 70.3 | F23: 62.5 | G23: 59.6 | H23: 56.8 | I23: 58.4 | J23: 61.5 | K23: 69.2 | L23: 65.3 | M23: 69.2 | N23: 61.9 | O23: 57.9 | P23: 54.5 | Q23: 48.9
A24: -16 | B24: Non-cash charges | C24: 47.6 | D24: 40.6 | E24: 33.8 | F24: 32.4 | G24: 27.7 | H24: 23.3 | I24: 23.6 | J24: 21.8 | K24: 18.1 | L24: 15.1 | M24: 14.3 | N24: 12.5 | O24: 11.3 | P24: 10.4 | Q24: 9.3
A25: -17 | B25: Cash from operations | C25: 104 | D25: 108.9 | E25: 104 | F25: 95 | G25: 87.3 | H25: 80 | I25: 82.1 | J25: 83.3 | K25: 87.3 | L25: 80.4 | M25: 83.5 | N25: 74.4 | O25: 69.1 | P25: 64.9 | Q25: 58.2
A26: -18 | B26: Capital expenditures | C26: 42.6 | D26: 33.8 | E26: 41.8 | F26: 57.5 | G26: 34.1 | H26: 9.4 | I26: 1.9 | J26: 2.6 | K26: 2 | L26: 3.9 | M26: 11 | N26: 0 | O26: 0.6 | P26: 1.1 | Q26: 0.2
A28: -19 | B28: Cash flow | C28: 61.4 | D28: 75.1 | E28: 62.2 | F28: 37.4 | G28: 53.2 | H28: 70.7 | I28: 80.2 | J28: 80.7 | K28: 85.3 | L28: 76.5 | M28: 72.5 | N28: 74.3 | O28: 68.5 | P28: 63.8 | Q28: 58
A30: -20 | B30: Terminal value | Q30: 283.1
A32: -21 | B32: Cumulative cash flow | C32: 61.4 | D32: 136.5 | E32: 198.8 | F32: 236.2 | G32: 289.3 | H32: 360 | I32: 440.2 | J32: 520.9 | K32: 606.2 | L32: 682.7 | M32: 755.2 | N32: 829.5 | O32: 898 | P32: 961.8 | Q32: 1302.9
A35: Notes follow Exhibit 7.

Sheet Exhibit 10
A1: Exhibit 10 Selected Contemporary Financial Market Data
A3: U.S. Government Bond Yields, Year-end 1990
A5: Term | B5: Yield
A7: 30-day | B7: 0.0652
A8: 10-year | B8: 0.0803
A9: 30-year | B9: 0.0824
A12: Note: Yields are expressed on a bond-equivalent basis.
A15: Industrial Bond Yields
A17: Rating | B17: 33208 | C17: 33239 | D17: 33270
A20: AAA | B20: 0.0908 | C20: 0.0895 | D20: 0.088
A21: AA | B21: 0.0945 | C21: 0.094 | D21: 0.0909
A22: A | B22: 0.0954 | C22: 0.095 | D22: 0.0929
A23: BBB | B23: 0.1155 | C23: 0.1167 | D23: 0.1038
A24: BB | B24: 0.1241 | C24: 0.1224 | D24: 0.123
A25: B | B25: 0.1902 | C25: 0.202 | D25: 0.1737
A28: Sources: Wall Street Journal, Morgan Stanley, Standard & Poor’s.

Sheet DCF
B1: 1990 | C1: 1991 | D1: 1992 | E1: 1993 | F1: 1994 | G1: 1995 | H1: 1996 | I1: 1997 | J1: 1998 | K1: 1999 | L1: 2000 | M1: 2001 | N1: 2002 | O1: 2003 | P1: 2004 | Q1: 2005
A2: Proved Developed | T2: CAPM
A3: FCF | C3: ='Exhibit 3'!C28 -> 89.4 | D3: ='Exhibit 3'!D28 -> 80 | E3: ='Exhibit 3'!E28 -> 69.6 | F3: ='Exhibit 3'!F28 -> 63 | G3: ='Exhibit 3'!G28 -> 56 | H3: ='Exhibit 3'!H28 -> 49.5 | I3: ='Exhibit 3'!I28 -> 44.9 | J3: ='Exhibit 3'!J28 -> 41.9 | ... Q3: ='Exhibit 3'!Q28 -> 22.1 | T3: Unlevered Beta | U3: ='Exhibit 2'!F52 -> 0.82
A4: PV (FCF) | C4: =C3/(1+$U$6)^1 -> 78.297425 | D4: =D3/(1+$U$6)^2 -> 61.36347 | E4: =E3/(1+$U$6)^3 -> 46.756191 | F4: =F3/(1+$U$6)^4 -> 37.066399 | G4: =G3/(1+$U$6)^5 -> 28.856113 | H4: =H3/(1+$U$6)^6 -> 22.339064 | I4: =I3/(1+$U$6)^7 -> 17.746637 | J4: =J3/(1+$U$6)^8 -> 14.504198 | K4: =K3/(1+$U$6)^9 -> 11.399282 | L4: =L3/(1+$U$6)^10 -> 9.1073858 | M4: =M3/(1+$U$6)^11 -> 7.953086 | N4: =N3/(1+$U$6)^12 -> 6.0081609 | O4: =O3/(1+$U$6)^13 -> 4.6555394 | P4: =P3/(1+$U$6)^14 -> 3.6711939 | Q4: =Q3/(1+$U$6)^15 -> 3.0237208 | T4: MRP | U4: 0.075
A5: Terminal Value | Q5: ='Exhibit 3'!Q30 -> 92.1 | T5: Risk Free Rate | U5: ='Exhibit 10'!B8 -> 0.0803
A6: PV (TV) | Q6: =Q5/(1+$U$6)^15 -> 12.601117 | T6: Cost of Equity | U6: =U5+U4*U3 -> 0.1418
A7: Reserve Value | B7: =SUM(C4:Q4,Q6) -> 365.34898 | C7: =(B7*(1+$U$6))-C3 -> 327.75547 | D7: =(C7*(1+$U$6))-D3 -> 294.23119 | E7: =(D7*(1+$U$6))-E3 -> 266.35318 | F7: =(E7*(1+$U$6))-F3 -> 241.12206 | G7: =(F7*(1+$U$6))-G3 -> 219.31317 | H7: =(G7*(1+$U$6))-H3 -> 200.91177 | I7: =(H7*(1+$U$6))-I3 -> 184.50106 | J7: =(I7*(1+$U$6))-J3 -> 168.76331 | ... Q7: =(P7*(1+$U$6))-Q3 -> 92.1 | T7: Cost of Debt | U7: 0.12
A8: Value | Q8: =SUM(C4:Q4,Q6) -> 365.34898 | T8: Debt Capacity | U8: 0.5
T9: Tax Rate | U9: =AVERAGE('Exhibit 3'!S38,'Exhibit 4'!S38) -> 0.35696859
A11: Proved Undeveloped
A12: FCF | C12: ='Exhibit 4'!C28 -> -13.5 | D12: ='Exhibit 4'!D28 -> -5.8 | E12: ='Exhibit 4'!E28 -> 7.6 | F12: ='Exhibit 4'!F28 -> 5.2 | G12: ='Exhibit 4'!G28 -> 4.6 | H12: ='Exhibit 4'!H28 -> 6.7 | I12: ='Exhibit 4'!I28 -> 9.7 | J12: ='Exhibit 4'!J28 -> 12.5 | ... Q12: ='Exhibit 4'!Q28 -> 15.1
A13: PV (FCF) | C13: =C12/(1+$U$6)^1 -> -11.823437 | D13: =D12/(1+$U$6)^2 -> -4.4488516 | E13: =E12/(1+$U$6)^3 -> 5.1055611 | F13: =F12/(1+$U$6)^4 -> 3.0594488 | G13: =G12/(1+$U$6)^5 -> 2.3703236 | H13: =H12/(1+$U$6)^6 -> 3.0236713 | I13: =I12/(1+$U$6)^7 -> 3.833906 | J13: =J12/(1+$U$6)^8 -> 4.327028 | K13: =K12/(1+$U$6)^9 -> 4.8507583 | L13: =L12/(1+$U$6)^10 -> 4.0093739 | M13: =M12/(1+$U$6)^11 -> 1.5813154 | N13: =N12/(1+$U$6)^12 -> 2.9938971 | O13: =O12/(1+$U$6)^13 -> 2.711272 | P13: =P12/(1+$U$6)^14 -> 2.5776468 | Q13: =Q12/(1+$U$6)^15 -> 2.0659812
A14: Terminal Value | Q14: ='Exhibit 4'!Q30 -> 67.8
A15: PV (TV) | Q15: =Q14/(1+$U$6)^15 -> 9.2763925
A16: Reserve Value | B16: =SUM(C13:Q13,Q15) -> 35.514288 | C16: =(B16*(1+$U$6))-C12 -> 54.050214 | D16: =(C16*(1+$U$6))-D12 -> 67.514534 | E16: =(D16*(1+$U$6))-E12 -> 69.488095 | F16: =(E16*(1+$U$6))-F12 -> 74.141507 | G16: =(F16*(1+$U$6))-G12 -> 80.054772 | H16: =(G16*(1+$U$6))-H12 -> 84.706539 | I16: =(H16*(1+$U$6))-I12 -> 87.017926 | J16: =(I16*(1+$U$6))-J12 -> 86.857068 | ... Q16: =(P16*(1+$U$6))-Q12 -> 67.8
A17: Value | Q17: =SUM(C13:Q13,Q15) -> 35.514288
A20: Debt Structure
A21: Debt Capacity | B21: =$U$8*(B7+B16) -> 200.43164 | C21: =$U$8*(C7+C16) -> 190.90284 | D21: =$U$8*(D7+D16) -> 180.87286 | E21: =$U$8*(E7+E16) -> 167.92064 | F21: =$U$8*(F7+F16) -> 157.63178 | G21: =$U$8*(G7+G16) -> 149.68397 | H21: =$U$8*(H7+H16) -> 142.80916 | I21: =$U$8*(I7+I16) -> 135.75949 | ... Q21: =$U$8*(Q7+Q16) -> 79.95
A22: Interest | C22: =C21*$U$7 -> 22.908341 | D22: =D21*$U$7 -> 21.704744 | E22: =E21*$U$7 -> 20.150476 | F22: =F21*$U$7 -> 18.915814 | G22: =G21*$U$7 -> 17.962076 | H22: =H21*$U$7 -> 17.137099 | I22: =I21*$U$7 -> 16.291139 | J22: =J21*$U$7 -> 15.337223 | ... Q22: =Q21*$U$7 -> 9.594
A23: Tax Shield | C23: =C22*$U$9 -> 8.1775583 | D23: =D22*$U$9 -> 7.7479118 | E23: =E22*$U$9 -> 7.1930872 | F23: =F22*$U$9 -> 6.7523515 | G23: =G22*$U$9 -> 6.4118971 | H23: =H22*$U$9 -> 6.117406 | I23: =I22*$U$9 -> 5.8154251 | J23: =J22*$U$9 -> 5.4749069 | ... Q23: =Q22*$U$9 -> 3.4247567
A24: PV (TS) | C24: =C23/(1+$U$7)^1 -> 7.3013913 | D24: =D23/(1+$U$7)^2 -> 6.1765879 | E24: =E23/(1+$U$7)^3 -> 5.1198974 | F24: =F23/(1+$U$7)^4 -> 4.2912414 | G24: =G23/(1+$U$7)^5 -> 3.6382826 | H24: =H23/(1+$U$7)^6 -> 3.0992683 | I24: =I23/(1+$U$7)^7 -> 2.630603 | J24: =J23/(1+$U$7)^8 -> 2.2112231 | K24: =K23/(1+$U$7)^9 -> 1.8402787 | L24: =L23/(1+$U$7)^10 -> 1.535433 | M24: =M23/(1+$U$7)^11 -> 1.3128741 | N24: =N23/(1+$U$7)^12 -> 1.0954389 | O24: =O23/(1+$U$7)^13 -> 0.91404059 | P24: =P23/(1+$U$7)^14 -> 0.75652891 | Q24: =Q23/(1+$U$7)^15 -> 0.62569024
A25: Value | Q25: =SUM(B24:Q24) -> 42.548779
A28: Probable
A29: FCF | C29: ='Exhibit 5'!C28 -> -5.8 | D29: ='Exhibit 5'!D28 -> 3.8 | E29: ='Exhibit 5'!E28 -> -1.5 | F29: ='Exhibit 5'!F28 -> -2.5 | G29: ='Exhibit 5'!G28 -> 9.7 | H29: ='Exhibit 5'!H28 -> 11.9 | I29: ='Exhibit 5'!I28 -> 13.1 | J29: ='Exhibit 5'!J28 -> 13 | ... Q29: ='Exhibit 5'!Q28 -> 6.4
A30: PV (FCF) | C30: =C29/(1+$U$6)^1 -> -5.0796987 | D30: =D29/(1+$U$6)^2 -> 2.9147648 | E30: =E29/(1+$U$6)^3 -> -1.0076765 | F30: =F29/(1+$U$6)^4 -> -1.4708888 | G30: =G29/(1+$U$6)^5 -> 4.998291 | H30: =H29/(1+$U$6)^6 -> 5.3704012 | I30: =I29/(1+$U$6)^7 -> 5.1777494 | J30: =J29/(1+$U$6)^8 -> 4.5001091 | K30: =K29/(1+$U$6)^9 -> 4.0018756 | L30: =L29/(1+$U$6)^10 -> 2.920736 | M30: =M29/(1+$U$6)^11 -> 2.371973 | N30: =N29/(1+$U$6)^12 -> 2.0366647 | O30: =O29/(1+$U$6)^13 -> 1.4983345 | P30: =P29/(1+$U$6)^14 -> 1.0935471 | Q30: =Q29/(1+$U$6)^15 -> 0.87564767
A31: Terminal Value | Q31: ='Exhibit 5'!Q30 -> 51
A32: PV (TV) | Q32: =Q31/(1+$U$6)^15 -> 6.9778173
A33: Value | Q33: =SUM(C30:Q30,Q32) -> 37.179647
A36: Possible
A37: FCF | C37: ='Exhibit 6'!C28 -> -8.6 | D37: ='Exhibit 6'!D28 -> -2.9 | E37: ='Exhibit 6'!E28 -> -13.5 | F37: ='Exhibit 6'!F28 -> -28.4 | G37: ='Exhibit 6'!G28 -> -17.1 | H37: ='Exhibit 6'!H28 -> 2.5 | I37: ='Exhibit 6'!I28 -> 12.5 | J37: ='Exhibit 6'!J28 -> 13.4 | ... Q37: ='Exhibit 6'!Q28 -> 14.4
A38: PV (FCF) | C38: =C37/(1+$U$6)^1 -> -7.5319671 | D38: =D37/(1+$U$6)^2 -> -2.2244258 | E38: =E37/(1+$U$6)^3 -> -9.0690888 | F38: =F37/(1+$U$6)^4 -> -16.709297 | G38: =G37/(1+$U$6)^5 -> -8.8114203 | H38: =H37/(1+$U$6)^6 -> 1.1282355 | I38: =I37/(1+$U$6)^7 -> 4.9406005 | J38: =J37/(1+$U$6)^8 -> 4.638574 | K38: =K37/(1+$U$6)^9 -> 5.6086893 | L38: =L37/(1+$U$6)^10 -> 4.2748954 | M38: =M37/(1+$U$6)^11 -> 4.9299832 | N38: =N37/(1+$U$6)^12 -> 4.093696 | O38: =O37/(1+$U$6)^13 -> 3.3534153 | P38: =P37/(1+$U$6)^14 -> 2.6245131 | Q38: =Q37/(1+$U$6)^15 -> 1.9702072
A39: Terminal Value | Q39: ='Exhibit 6'!Q30 -> 72.3
A40: PV (TV) | Q40: =Q39/(1+$U$6)^15 -> 9.8920822
A41: Value | Q41: =SUM(C38:Q38,Q40) -> 3.1086926
A44: Total Value | Q44: =SUM(Q8,Q17,Q25,Q33,Q41) -> 483.70039

Sheet Real Options
B2: Black-Scholes | F2: Proved Undeveloped | X2: Years to Wait / Volatility | Y2: 0.3 | Z2: 0.35 | AA2: 0.4 | AB2: 0.45 | AC2: 0.5
B3: S (Asset Value) | C3: =V8 -> 64.417632 | F3: FCF | H3: 4 | I3: 11.9 | J3: 7.6 | K3: 5.2 | L3: 4.6 | M3: 6.7 | N3: 9.7 | O3: 12.5 | P3: 16 | Q3: 15.1 | R3: 6.8 | S3: 14.7 | T3: 15.2 | U3: 16.5 | V3: 15.1 | X3: 1 | Y3: 35.487318 | Z3: 35.529147 | AA3: 35.616544 | AB3: 35.759897 | AC3: 35.962594
B4: K (Strike) | C4: =('Exhibit 4'!C26/(1+'Real Options'!C5)^1)+('Exhibit 4'!D26/(1+'Real Options'!C5)^2) -> 31.365674 | F4: PV (FCF) | H4: 3.5032405 | I4: 9.1278161 | J4: 5.1055611 | K4: 3.0594488 | L4: 2.3703236 | M4: 3.0236713 | N4: 3.833906 | O4: 4.327028 | P4: 4.8507583 | Q4: 4.0093739 | R4: 1.5813154 | S4: 2.9938971 | T4: 2.711272 | U4: 2.5776468 | V4: 2.0659812 | X4: 2 | Y4: 37.825442 | Z4: 38.007892 | AA4: 38.292572 | AB4: 38.674766 | AC4: 39.14286
B5: r (Risk-free) | C5: ='Exhibit 10'!B8 -> 0.0803 | F5: Terminal Value | V5: 67.8 | X5: 3 | Y5: 40.021317 | Z5: 40.329653 | AA5: 40.766449 | AB5: 41.314713 | AC5: 41.953764
B6: σ (Volatility) | C6: 0.4 | F6: PV (TV) | V6: 9.2763925 | X6: 4 | Y6: 42.041629 | Z6: 42.442851 | AA6: 42.985149 | AB6: 43.643281 | AC6: 44.390838
B7: T (Years to wait) | C7: 7 | F7: Reserve Value | G7: 64.417632 | H7: 69.552053 | I7: 67.514534 | J7: 69.488095 | K7: 74.141507 | L7: 80.054772 | M7: 84.706539 | N7: 87.017926 | O7: 86.857068 | P7: 83.1734 | Q7: 79.867388 | R7: 84.392584 | S7: 81.659452 | T7: 78.038763 | U7: 72.604659 | V7: 67.8 | X7: 5 | Y7: 43.887836 | Z7: 44.353905 | AA7: 44.967082 | AB7: 45.696339 | AC7: 46.511269
B8: d1 | C8: =(LN(C3/C4) + (C5 + 0.5*C6^2)*C7) / (C6*SQRT(C7)) -> 1.7403122 | F8: Value | V8: 64.417632 | X8: 6 | Y8: 45.572185 | Z8: 46.081498 | AA8: 46.740303 | AB8: 47.513352 | AC8: 48.367278
B9: d2 | C9: =C8 - C6*SQRT(C7) -> 0.68201164 | X9: 7 | Y9: 47.109141 | Z9: 47.645303 | AA9: 48.331109 | AB9: 49.128157 | AC9: 50.000831
B10: N(d1) | C10: =_xlfn.NORM.S.DIST(C8, TRUE) -> 0.95909789
B11: N(d2) | C11: =_xlfn.NORM.S.DIST(C9, TRUE) -> 0.75238421
B12: Call Value | C12: =C3*C10 - C4*EXP(-C5*C7)*C11 -> 48.331109
B17: Black-Scholes | F17: Probable | X17: Years to Wait / Volatility | Y17: 0.3 | Z17: 0.35 | AA17: 0.4 | AB17: 0.45 | AC17: 0.5
B18: S (Asset Value) | C18: =V22 -> 66.471102 | F18: FCF | H18: 4.2 | I18: 8.1 | J18: 9.9 | K18: 11.5 | L18: 12.3 | M18: 11.9 | N18: 13.1 | O18: 13 | P18: 13.2 | Q18: 11 | R18: 10.2 | S18: 10 | T18: 8.4 | U18: 7 | V18: 6.4 | X18: 1 | Y18: 35.094687 | Z18: 35.158243 | AA18: 35.279865 | AB18: 35.467771 | AC18: 35.722444
B19: K (Strike) | C19: =('Exhibit 5'!C26/(1+'Real Options'!C20)^1)+('Exhibit 5'!D26/(1+'Real Options'!C20)^2)+('Exhibit 5'!E26/(1+'Real Options'!C20)^3)+('Exhibit 5'!F26/(1+'Real Options'!C20)^4)+('Exhibit 5'!G26/(1+'Real Options'!C20)^5) -> 34.029401 | F19: PV (FCF) | H19: 3.6784025 | I19: 6.2130513 | J19: 6.6506651 | K19: 6.7660887 | L19: 6.3380392 | M19: 5.3704012 | N19: 5.1777494 | O19: 4.5001091 | P19: 4.0018756 | Q19: 2.920736 | R19: 2.371973 | S19: 2.0366647 | T19: 1.4983345 | U19: 1.0935471 | V19: 0.87564767 | X19: 2 | Y19: 37.664898 | Z19: 37.901017 | AA19: 38.251663 | AB19: 38.706952 | AC19: 39.251589
B20: r (Risk-free) | C20: ='Exhibit 10'!B8 -> 0.0803 | F20: Terminal Value | V20: 51 | X20: 3 | Y20: 40.070282 | Z20: 40.4483 | AA20: 40.964719 | AB20: 41.597264 | AC20: 42.321968
B21: σ (Volatility) | C21: 0.4 | F21: PV (TV) | V21: 6.9778173 | X21: 4 | Y21: 42.273902 | Z21: 42.752607 | AA21: 43.380731 | AB21: 44.127961 | AC21: 44.964892
B22: T (Years to wait) | C22: 7 | F22: Value | V22: 66.471102 | X22: 5 | Y22: 44.281408 | Z22: 44.828467 | AA22: 45.529979 | AB22: 46.350032 | AC22: 47.25538
B23: d1 | C23: =(LN(C18/C19) + (C20 + 0.5*C21^2)*C22) / (C21*SQRT(C22)) -> 1.692943 | X23: 6 | Y23: 46.109002 | Z23: 46.700328 | AA23: 47.447864 | AB23: 48.311599 | AC23: 49.255403
B24: d2 | C24: =C23 - C21*SQRT(C22) -> 0.63464244 | X24: 7 | Y24: 47.774176 | Z24: 48.391833 | AA24: 49.165441 | AB24: 50.051915 | AC24: 51.012903
B25: N(d1) | C25: =_xlfn.NORM.S.DIST(C23, TRUE) -> 0.95476684
B26: N(d2) | C26: =_xlfn.NORM.S.DIST(C24, TRUE) -> 0.73716918
B27: Call Value | C27: =C18*C25 - C19*EXP(-C20*C22)*C26 -> 49.165441
B32: Black-Scholes | F32: Possible | X32: Years to Wait / Volatility | Y32: 0.3 | Z32: 0.35 | AA32: 0.4 | AB32: 0.45 | AC32: 0.5
B33: S (Asset Value) | C33: =V37 -> 71.17496 | F33: FCF | H33: 1.1 | I33: 6.9 | J33: 8.9 | K33: 10.5 | L33: 10.3 | M33: 2.5 | N33: 12.5 | O33: 13.4 | P33: 18.5 | Q33: 16.1 | R33: 21.2 | S33: 20.1 | T33: 18.8 | U33: 16.8 | V33: 14.4 | X33: 1 | Y33: 6.5782314 | Z33: 7.9967205 | AA33: 9.4161933 | AB33: 10.833367 | AC33: 12.24593
B34: K (Strike) | C34: =('Exhibit 6'!C26/(1+'Real Options'!C35)^1)+('Exhibit 6'!D26/(1+'Real Options'!C35)^2)+('Exhibit 6'!E26/(1+'Real Options'!C35)^3)+('Exhibit 6'!F26/(1+'Real Options'!C35)^4)+('Exhibit 6'!G26/(1+'Real Options'!C35)^5) -> 82.326289 | F34: PV (FCF) | H34: 0.96339114 | I34: 5.2925993 | J34: 5.9788807 | K34: 6.1777331 | L34: 5.3074637 | M34: 1.1282355 | N34: 4.9406005 | O34: 4.638574 | P34: 5.6086893 | Q34: 4.2748954 | R34: 4.9299832 | S34: 4.093696 | T34: 3.3534153 | U34: 2.6245131 | V34: 1.9702072 | X34: 2 | Y34: 12.406757 | Z34: 14.346438 | AA34: 16.269481 | AB34: 18.173564 | AC34: 20.056466
B35: r (Risk-free) | C35: ='Exhibit 10'!B8 -> 0.0803 | F35: Terminal Value | V35: 72.3 | X35: 3 | Y35: 17.391472 | Z35: 19.612533 | AA35: 21.812561 | AB35: 23.985061 | AC35: 26.124814
B36: σ (Volatility) | C36: 0.4 | F36: PV (TV) | V36: 9.8920822 | X36: 4 | Y36: 21.80065 | Z36: 24.17838 | AA36: 26.536427 | AB36: 28.861986 | AC36: 31.145583
B37: T (Years to wait) | C37: 7 | F37: Value | V37: 71.17496 | X37: 5 | Y37: 25.762858 | Z37: 28.219209 | AA37: 30.660202 | AB37: 33.065832 | AC37: 35.421855
B38: d1 | C38: =(LN(C33/C34) + (C35 + 0.5*C36^2)*C37) / (C36*SQRT(C37)) -> 0.92275356 | X38: 6 | Y38: 29.354784 | Z38: 31.836913 | AA38: 34.309596 | AB38: 36.745385 | AC38: 39.125156
B39: d2 | C39: =C38 - C36*SQRT(C37) -> -0.13554696 | X39: 7 | Y39: 32.628697 | Z39: 35.099422 | AA39: 37.567394 | AB39: 39.997864 | AC39: 42.366938
B40: N(d1) | C40: =_xlfn.NORM.S.DIST(C38, TRUE) -> 0.82193218
B41: N(d2) | C41: =_xlfn.NORM.S.DIST(C39, TRUE) -> 0.44608972
B42: Call Value | C42: =C33*C40 - C34*EXP(-C35*C37)*C41 -> 37.567394
